Workbook

Sheet Detail
A1: Gulfside Hospitality Group | Purchase Detail | Jan 2025 to Jun 2026
A2: AP invoice export, run 07/03/2026. Amounts in USD.
A3: Invoice # | B3: Invoice Date | C3: Vendor | D3: Location | E3: Item # | F3: Description | G3: Category | H3: Pack | I3: UOM | J3: Qty | K3: Unit Price | L3: Ext Price
A4: GB01-0002 | B4: 45658 | C4: Gulf Breeze Produce | D4: Palm Key | E4: GB-522 | F4: BANANA GREEN TIP | G4: Produce | H4: 1/40 LB | I4: CS | J4: 1 | K4: 25.28 | L4: 25.28
A5: GB01-0002 | B5: 45658 | C5: Gulf Breeze Produce | D5: Palm Key | E5: GB-463 | F5: ORANGE NAVEL 88 CT | G5: Produce | H5: 1/88 CT | I5: CS | J5: 1 | K5: 45.78 | L5: 45.78
A6: GB01-0002 | B6: 45658 | C6: Gulf Breeze Produce | D6: Palm Key | E6: GB-251 | F6: ONION YELLOW JUMBO | G6: Produce | H6: 1/50 LB | I6: CS | J6: 2 | K6: 24.68 | L6: 49.36
A7: GB01-0002 | B7: 45658 | C7: Gulf Breeze Produce | D7: Palm Key | E7: GB-573 | F7: BASIL FRESH | G7: Produce | H7: 1/1 LB | I7: EA | J7: 10 | K7: 14.72 | L7: 147.2
A8: GB01-0002 | B8: 45658 | C8: Gulf Breeze Produce | D8: Palm Key | E8: GB-487 | F8: STRAWBERRY | G8: Produce | H8: 8/1 LB | I8: CS | J8: 6 | K8: 27.98 | L8: 167.88
A9: GB01-0002 | B9: 45658 | C9: Gulf Breeze Produce | D9: Palm Key | E9: GB-566 | F9: CILANTRO | G9: Produce | H9: 1/30 BU | I9: CS | J9: 1 | K9: 21.81 | L9: 21.81
A10: GB01-0002 | B10: 45658 | C10: Gulf Breeze Produce | D10: Palm Key | E10: GB-172 | F10: SPINACH BABY | G10: Produce | H10: 1/4 LB | I10: CS | J10: 1 | K10: 14.62 | L10: 14.62
A11: GB01-0002 | B11: 45658 | C11: Gulf Breeze Produce | D11: Palm Key | E11: FEE-FUEL | F11: FUEL SURCHARGE | G11: Fees | I11: EA | J11: 1 | K11: 6 | L11: 6
A12: GB01-0003 | B12: 45658 | C12: Gulf Breeze Produce | D12: Harborlight | E12: GB-522 | F12: BANANA GREEN TIP | G12: Produce | H12: 1/40 LB | I12: CS | J12: 8 | K12: 24.67 | L12: 197.36
A13: GB01-0003 | B13: 45658 | C13: Gulf Breeze Produce | D13: Harborlight | E13: GB-338 | F13: CELERY 30 CT | G13: Produce | H13: 1/30 CT | I13: CS | J13: 2 | K13: 33.43 | L13: 66.86
A14: GB01-0003 | B14: 45658 | C14: Gulf Breeze Produce | D14: Harborlight | E14: GB-186 | F14: ARUGULA BABY | G14: Produce | H14: 1/3 LB | I14: CS | J14: 2 | K14: 16.89 | L14: 33.78
A15: GB01-0003 | B15: 45658 | C15: Gulf Breeze Produce | D15: Harborlight | E15: GB-430 | F15: MUSHROOM WHITE LARGE | G15: Produce | H15: 1/10 LB | I15: CS | J15: 8 | K15: 21.22 | L15: 169.76
A16: GB01-0003 | B16: 45658 | C16: Gulf Breeze Produce | D16: Harborlight | E16: GB-573 | F16: BASIL FRESH | G16: Produce | H16: 1/1 LB | I16: EA | J16: 2 | K16: 14.72 | L16: 29.44
A17: GB01-0003 | B17: 45658 | C17: Gulf Breeze Produce | D17: Harborlight | E17: GB-216 | F17: TOMATO GRAPE | G17: Produce | H17: 12/1 PT | I17: CS | J17: 6 | K17: 23.03 | L17: 138.18
A18: GB01-0003 | B18: 45658 | C18: Gulf Breeze Produce | D18: Harborlight | E18: GB-444 | F18: LEMON 115 CT | G18: Produce | H18: 1/115 CT | I18: CS | J18: 2 | K18: 37.09 | L18: 74.18
A19: GB01-0003 | B19: 45658 | C19: Gulf Breeze Produce | D19: Harborlight | E19: GB-172 | F19: SPINACH BABY | G19: Produce | H19: 1/4 LB | I19: CS | J19: 1 | K19: 14.82 | L19: 14.82
A20: GB01-0003 | B20: 45658 | C20: Gulf Breeze Produce | D20: Harborlight | E20: GB-251 | F20: ONION YELLOW JUMBO | G20: Produce | H20: 1/50 LB | I20: CS | J20: 1 | K20: 24.7 | L20: 24.7
A21: GB01-0003 | B21: 45658 | C21: Gulf Breeze Produce | D21: Harborlight | E21: GB-115 | F21: LETTUCE ROMAINE HEARTS | G21: Produce | H21: 3/6 CT | I21: CS | J21: 8 | K21: 24.63 | L21: 197.04
A22: GB01-0003 | B22: 45658 | C22: Gulf Breeze Produce | D22: Harborlight | E22: GB-463 | F22: ORANGE NAVEL 88 CT | G22: Produce | H22: 1/88 CT | I22: CS | J22: 3 | K22: 45 | L22: 135
A23: GB01-0003 | B23: 45658 | C23: Gulf Breeze Produce | D23: Harborlight | E23: GB-168 | F23: SPRING MIX | G23: Produce | H23: 1/3 LB | I23: CS | J23: 3 | K23: 14.18 | L23: 42.54
... A25: GB01-0003 | B25: 45658 | C25: Gulf Breeze Produce | D25: Harborlight | E25: GB-559 | F25: CANTALOUPE 12 CT | G25: Produce | H25: 1/12 CT | I25: CS | J25: 3 | K25: 31.58 | L25: 94.74
A26: GB01-0003 | B26: 45658 | C26: Gulf Breeze Produce | D26: Harborlight | E26: FEE-FUEL | F26: FUEL SURCHARGE | G26: Fees | I26: EA | J26: 1 | K26: 6 | L26: 6
A27: GB01-0004 | B27: 45658 | C27: Gulf Breeze Produce | D27: Palm Key | E27: GB-135 | F27: LETTUCE ICEBERG | G27: Produce | H27: 1/24 CT | I27: CS | J27: 4 | K27: 28.82 | L27: 115.28
A28: GB01-0004 | B28: 45658 | C28: Gulf Breeze Produce | D28: Palm Key | E28: GB-306 | F28: POTATO RED B | G28: Produce | H28: 1/50 LB | I28: CS | J28: 5 | K28: 34.39 | L28: 171.95
A29: GB01-0004 | B29: 45658 | C29: Gulf Breeze Produce | D29: Palm Key | E29: GB-338 | F29: CELERY 30 CT | G29: Produce | H29: 1/30 CT | I29: CS | J29: 1 | K29: 33.35 | L29: 33.35
A30: GB01-0004 | B30: 45658 | C30: Gulf Breeze Produce | D30: Palm Key | E30: GB-251 | F30: ONION YELLOW JUMBO | G30: Produce | H30: 1/50 LB | I30: CS | J30: 8 | K30: 24.55 | L30: 196.4
A31: GB01-0004 | B31: 45658 | C31: Gulf Breeze Produce | D31: Palm Key | E31: GB-406 | F31: ZUCCHINI MEDIUM | G31: Produce | H31: 1/20 LB | I31: CS | J31: 4 | K31: 23.26 | L31: 93.04
A32: GB01-0004 | B32: 45658 | C32: Gulf Breeze Produce | D32: Palm Key | E32: GB-573 | F32: BASIL FRESH | G32: Produce | H32: 1/1 LB | I32: EA | J32: 11 | K32: 14.46 | L32: 159.06
A33: GB01-0004 | B33: 45658 | C33: Gulf Breeze Produce | D33: Palm Key | E33: GB-115 | F33: LETTUCE ROMAINE HEARTS | G33: Produce | H33: 3/6 CT | I33: CS | J33: 3 | K33: 24.6 | L33: 73.8
A34: GB01-0004 | B34: 45658 | C34: Gulf Breeze Produce | D34: Palm Key | E34: GB-430 | F34: MUSHROOM WHITE LARGE | G34: Produce | H34: 1/10 LB | I34: CS | J34: 1 | K34: 21.55 | L34: 21.55
A35: GB01-0004 | B35: 45658 | C35: Gulf Breeze Produce | D35: Palm Key | E35: GB-522 | F35: BANANA GREEN TIP | G35: Produce | H35: 1/40 LB | I35: CS | J35: 3 | K35: 25.12 | L35: 75.36
A36: GB01-0004 | B36: 45658 | C36: Gulf Breeze Produce | D36: Palm Key | E36: GB-444 | F36: LEMON 115 CT | G36: Produce | H36: 1/115 CT | I36: CS | J36: 2 | K36: 37.62 | L36: 75.24
A37: GB01-0004 | B37: 45658 | C37: Gulf Breeze Produce | D37: Palm Key | E37: FEE-FUEL | F37: FUEL SURCHARGE | G37: Fees | I37: EA | J37: 1 | K37: 6 | L37: 6
A38: GB01-0006 | B38: 45658 | C38: Gulf Breeze Produce | D38: Palm Key | E38: GB-493 | F38: BLUEBERRY | G38: Produce | H38: 12/6 OZ | I38: CS | J38: 2 | K38: 37.17 | L38: 74.34
A39: GB01-0006 | B39: 45658 | C39: Gulf Breeze Produce | D39: Palm Key | E39: GB-522 | F39: BANANA GREEN TIP | G39: Produce | H39: 1/40 LB | I39: CS | J39: 1 | K39: 24.61 | L39: 24.61
A40: GB01-0006 | B40: 45658 | C40: Gulf Breeze Produce | D40: Palm Key | E40: GB-256 | F40: ONION RED JUMBO | G40: Produce | H40: 1/25 LB | I40: CS | J40: 1 | K40: 21.26 | L40: 21.26
A41: GB01-0006 | B41: 45658 | C41: Gulf Breeze Produce | D41: Palm Key | E41: GB-573 | F41: BASIL FRESH | G41: Produce | H41: 1/1 LB | I41: EA | J41: 4 | K41: 14.36 | L41: 57.44
...

Sheet Price File
A1: Item # | B1: Description | C1: Vendor | D1: Pack | E1: UOM | F1: Contract Price | G1: Category
A2: CP10108 | B2: FLOUR ALL PURPOSE BLEACHED | C2: Coastline Provisions | D2: 1/50 LB | E2: CS | F2: 24.8 | G2: Dry Goods
A3: CP10143 | B3: SUGAR GRANULATED CANE | C3: Coastline Provisions | D3: 1/50 LB | E3: CS | F3: 41.5 | G3: Dry Goods
A4: CP10175 | B4: RICE LONG GRAIN PARBOILED | C4: Coastline Provisions | D4: 1/25 LB | E4: CS | F4: 22.4 | G4: Dry Goods
A5: CP10204 | B5: PASTA PENNE RIGATE | C5: Coastline Provisions | D5: 2/10 LB | E5: CS | F5: 26.9 | G5: Dry Goods
A6: CP10208 | B6: PASTA SPAGHETTI 10 IN | C6: Coastline Provisions | D6: 2/10 LB | E6: CS | F6: 25.7 | G6: Dry Goods
A7: CP10231 | B7: TOMATO DICED IN JUICE | C7: Coastline Provisions | D7: 6/#10 | E7: CS | F7: 38.6 | G7: Dry Goods
A8: CP10267 | B8: TOMATO SAUCE FANCY | C8: Coastline Provisions | D8: 6/#10 | E8: CS | F8: 34.2 | G8: Dry Goods
A9: CP10296 | B9: BEANS BLACK | C9: Coastline Provisions | D9: 6/#10 | E9: CS | F9: 36.1 | G9: Dry Goods
A10: CP10331 | B10: OIL OLIVE EXTRA VIRGIN | C10: Coastline Provisions | D10: 6/1 LT | E10: CS | F10: 58 | G10: Dry Goods
A11: CP10376 | B11: VINEGAR WHITE DISTILLED | C11: Coastline Provisions | D11: 4/1 GAL | E11: CS | F11: 14.3 | G11: Dry Goods
A12: CP10395 | B12: SALT KOSHER COARSE | C12: Coastline Provisions | D12: 12/3 LB | E12: CS | F12: 27.6 | G12: Dry Goods
A13: CP10408 | B13: PEPPER BLACK GROUND | C13: Coastline Provisions | D13: 1/18 OZ | E13: EA | F13: 12.4 | G13: Dry Goods
... A170: MCR-93 | B170: COFFEE ESPRESSO BLEND | C170: Mangrove Coffee Roasters | D170: 1/5 LB | E170: EA | F170: 60 | G170: Beverage

Sheet Summary
A1: Spend Summary by Vendor and Location
A2: Built from the Detail tab with SUMIFS. Credits and fees included.
A4: Vendor | B4: Palm Key | C4: Harborlight | D4: Sandpiper | E4: CMSY | F4: Total | G4: Share of Total
A5: Coastline Provisions | B5: =SUMIFS(Detail!$L$4:$L$6003,Detail!$C$4:$C$6003,$A5,Detail!$D$4:$D$6003,B$4) -> 133185.55 | C5: =SUMIFS(Detail!$L$4:$L$6003,Detail!$C$4:$C$6003,$A5,Detail!$D$4:$D$6003,C$4) -> 80578.81 | D5: =SUMIFS(Detail!$L$4:$L$6003,Detail!$C$4:$C$6003,$A5,Detail!$D$4:$D$6003,D$4) -> 96441.81 | E5: =SUMIFS(Detail!$L$4:$L$6003,Detail!$C$4:$C$6003,$A5,Detail!$D$4:$D$6003,E$4) -> 0 | F5: =SUM(B5:E5) -> 310206.17 | G5: =F5/F$12 -> 0.37238509
A6: Bayfront Meats | B6: =SUMIFS(Detail!$L$4:$L$6003,Detail!$C$4:$C$6003,$A6,Detail!$D$4:$D$6003,B$4) -> 80012.62 | C6: =SUMIFS(Detail!$L$4:$L$6003,Detail!$C$4:$C$6003,$A6,Detail!$D$4:$D$6003,C$4) -> 60460.11 | D6: =SUMIFS(Detail!$L$4:$L$6003,Detail!$C$4:$C$6003,$A6,Detail!$D$4:$D$6003,D$4) -> 37575.88 | E6: =SUMIFS(Detail!$L$4:$L$6003,Detail!$C$4:$C$6003,$A6,Detail!$D$4:$D$6003,E$4) -> 14885.1 | F6: =SUM(B6:E6) -> 192933.71 | G6: =F6/F$12 -> 0.23160609
A7: Gulf Breeze Produce | B7: =SUMIFS(Detail!$L$4:$L$6003,Detail!$C$4:$C$6003,$A7,Detail!$D$4:$D$6003,B$4) -> 48172.86 | C7: =SUMIFS(Detail!$L$4:$L$6003,Detail!$C$4:$C$6003,$A7,Detail!$D$4:$D$6003,C$4) -> 44684.17 | D7: =SUMIFS(Detail!$L$4:$L$6003,Detail!$C$4:$C$6003,$A7,Detail!$D$4:$D$6003,D$4) -> 21881.51 | E7: =SUMIFS(Detail!$L$4:$L$6003,Detail!$C$4:$C$6003,$A7,Detail!$D$4:$D$6003,E$4) -> 5145.33 | F7: =SUM(B7:E7) -> 119883.87 | G7: =F7/F$12 -> 0.14391385
A8: Tidewater Seafood | B8: =SUMIFS(Detail!$L$4:$L$6003,Detail!$C$4:$C$6003,$A8,Detail!$D$4:$D$6003,B$4) -> 27008.26 | C8: =SUMIFS(Detail!$L$4:$L$6003,Detail!$C$4:$C$6003,$A8,Detail!$D$4:$D$6003,C$4) -> 24335.8 | D8: =SUMIFS(Detail!$L$4:$L$6003,Detail!$C$4:$C$6003,$A8,Detail!$D$4:$D$6003,D$4) -> 15956.49 | E8: =SUMIFS(Detail!$L$4:$L$6003,Detail!$C$4:$C$6003,$A8,Detail!$D$4:$D$6003,E$4) -> 0 | F8: =SUM(B8:E8) -> 67300.55 | G8: =F8/F$12 -> 0.080790531
A9: Sunrise Dairy Co | B9: =SUMIFS(Detail!$L$4:$L$6003,Detail!$C$4:$C$6003,$A9,Detail!$D$4:$D$6003,B$4) -> 24547.2 | C9: =SUMIFS(Detail!$L$4:$L$6003,Detail!$C$4:$C$6003,$A9,Detail!$D$4:$D$6003,C$4) -> 11220.74 | D9: =SUMIFS(Detail!$L$4:$L$6003,Detail!$C$4:$C$6003,$A9,Detail!$D$4:$D$6003,D$4) -> 10055.83 | E9: =SUMIFS(Detail!$L$4:$L$6003,Detail!$C$4:$C$6003,$A9,Detail!$D$4:$D$6003,E$4) -> 5768.29 | F9: =SUM(B9:E9) -> 51592.06 | G9: =F9/F$12 -> 0.061933371
A10: Keystone Paper & Chem | B10: =SUMIFS(Detail!$L$4:$L$6003,Detail!$C$4:$C$6003,$A10,Detail!$D$4:$D$6003,B$4) -> 25644.49 | C10: =SUMIFS(Detail!$L$4:$L$6003,Detail!$C$4:$C$6003,$A10,Detail!$D$4:$D$6003,C$4) -> 21842.7 | D10: =SUMIFS(Detail!$L$4:$L$6003,Detail!$C$4:$C$6003,$A10,Detail!$D$4:$D$6003,D$4) -> 9801.93 | E10: =SUMIFS(Detail!$L$4:$L$6003,Detail!$C$4:$C$6003,$A10,Detail!$D$4:$D$6003,E$4) -> 0 | F10: =SUM(B10:E10) -> 57289.12 | G10: =F10/F$12 -> 0.068772372
A11: Mangrove Coffee Roasters | B11: =SUMIFS(Detail!$L$4:$L$6003,Detail!$C$4:$C$6003,$A11,Detail!$D$4:$D$6003,B$4) -> 16114.93 | C11: =SUMIFS(Detail!$L$4:$L$6003,Detail!$C$4:$C$6003,$A11,Detail!$D$4:$D$6003,C$4) -> 8912.69 | D11: =SUMIFS(Detail!$L$4:$L$6003,Detail!$C$4:$C$6003,$A11,Detail!$D$4:$D$6003,D$4) -> 8792.12 | E11: =SUMIFS(Detail!$L$4:$L$6003,Detail!$C$4:$C$6003,$A11,Detail!$D$4:$D$6003,E$4) -> 0 | F11: =SUM(B11:E11) -> 33819.74 | G11: =F11/F$12 -> 0.040598699
A12: Total | B12: =SUM(B5:B11) -> 354685.91 | C12: =SUM(C5:C11) -> 252035.02 | D12: =SUM(D5:D11) -> 200505.57 | E12: =SUM(E5:E11) -> 25798.72 | F12: =SUM(F5:F11) -> 833025.22 | G12: =SUM(G5:G11) -> 1
A14: Category | B14: Palm Key | C14: Harborlight | D14: Sandpiper | E14: CMSY | F14: Total
A15: Beef | B15: =SUMIFS(Detail!$L$4:$L$6003,Detail!$G$4:$G$6003,$A15,Detail!$D$4:$D$6003,B$14) -> 52532.42 | C15: =SUMIFS(Detail!$L$4:$L$6003,Detail!$G$4:$G$6003,$A15,Detail!$D$4:$D$6003,C$14) -> 40102.95 | D15: =SUMIFS(Detail!$L$4:$L$6003,Detail!$G$4:$G$6003,$A15,Detail!$D$4:$D$6003,D$14) -> 23831.06 | E15: =SUMIFS(Detail!$L$4:$L$6003,Detail!$G$4:$G$6003,$A15,Detail!$D$4:$D$6003,E$14) -> 10982.89 | F15: =SUM(B15:E15) -> 127449.32
A16: Poultry | B16: =SUMIFS(Detail!$L$4:$L$6003,Detail!$G$4:$G$6003,$A16,Detail!$D$4:$D$6003,B$14) -> 28631.82 | C16: =SUMIFS(Detail!$L$4:$L$6003,Detail!$G$4:$G$6003,$A16,Detail!$D$4:$D$6003,C$14) -> 19041.36 | D16: =SUMIFS(Detail!$L$4:$L$6003,Detail!$G$4:$G$6003,$A16,Detail!$D$4:$D$6003,D$14) -> 17125.12 | E16: =SUMIFS(Detail!$L$4:$L$6003,Detail!$G$4:$G$6003,$A16,Detail!$D$4:$D$6003,E$14) -> 3902.21 | F16: =SUM(B16:E16) -> 68700.51
A17: Pork | B17: =SUMIFS(Detail!$L$4:$L$6003,Detail!$G$4:$G$6003,$A17,Detail!$D$4:$D$6003,B$14) -> 9684.41 | C17: =SUMIFS(Detail!$L$4:$L$6003,Detail!$G$4:$G$6003,$A17,Detail!$D$4:$D$6003,C$14) -> 6989.77 | D17: =SUMIFS(Detail!$L$4:$L$6003,Detail!$G$4:$G$6003,$A17,Detail!$D$4:$D$6003,D$14) -> 5345.93 | E17: =SUMIFS(Detail!$L$4:$L$6003,Detail!$G$4:$G$6003,$A17,Detail!$D$4:$D$6003,E$14) -> 0 | F17: =SUM(B17:E17) -> 22020.11
A18: Seafood | B18: =SUMIFS(Detail!$L$4:$L$6003,Detail!$G$4:$G$6003,$A18,Detail!$D$4:$D$6003,B$14) -> 26840.26 | C18: =SUMIFS(Detail!$L$4:$L$6003,Detail!$G$4:$G$6003,$A18,Detail!$D$4:$D$6003,C$14) -> 24191.8 | D18: =SUMIFS(Detail!$L$4:$L$6003,Detail!$G$4:$G$6003,$A18,Detail!$D$4:$D$6003,D$14) -> 15852.49 | E18: =SUMIFS(Detail!$L$4:$L$6003,Detail!$G$4:$G$6003,$A18,Detail!$D$4:$D$6003,E$14) -> 0 | F18: =SUM(B18:E18) -> 66884.55
A19: Produce | B19: =SUMIFS(Detail!$L$4:$L$6003,Detail!$G$4:$G$6003,$A19,Detail!$D$4:$D$6003,B$14) -> 47661.86 | C19: =SUMIFS(Detail!$L$4:$L$6003,Detail!$G$4:$G$6003,$A19,Detail!$D$4:$D$6003,C$14) -> 44203.17 | D19: =SUMIFS(Detail!$L$4:$L$6003,Detail!$G$4:$G$6003,$A19,Detail!$D$4:$D$6003,D$14) -> 21681.51 | E19: =SUMIFS(Detail!$L$4:$L$6003,Detail!$G$4:$G$6003,$A19,Detail!$D$4:$D$6003,E$14) -> 5145.33 | F19: =SUM(B19:E19) -> 118691.87
A20: Dairy | B20: =SUMIFS(Detail!$L$4:$L$6003,Detail!$G$4:$G$6003,$A20,Detail!$D$4:$D$6003,B$14) -> 39208.43 | C20: =SUMIFS(Detail!$L$4:$L$6003,Detail!$G$4:$G$6003,$A20,Detail!$D$4:$D$6003,C$14) -> 18756.47 | D20: =SUMIFS(Detail!$L$4:$L$6003,Detail!$G$4:$G$6003,$A20,Detail!$D$4:$D$6003,D$14) -> 17835.26 | E20: =SUMIFS(Detail!$L$4:$L$6003,Detail!$G$4:$G$6003,$A20,Detail!$D$4:$D$6003,E$14) -> 5768.29 | F20: =SUM(B20:E20) -> 81568.45
A21: Dry Goods | B21: =SUMIFS(Detail!$L$4:$L$6003,Detail!$G$4:$G$6003,$A21,Detail!$D$4:$D$6003,B$14) -> 59379.05 | C21: =SUMIFS(Detail!$L$4:$L$6003,Detail!$G$4:$G$6003,$A21,Detail!$D$4:$D$6003,C$14) -> 40057.16 | D21: =SUMIFS(Detail!$L$4:$L$6003,Detail!$G$4:$G$6003,$A21,Detail!$D$4:$D$6003,D$14) -> 45138.4 | E21: =SUMIFS(Detail!$L$4:$L$6003,Detail!$G$4:$G$6003,$A21,Detail!$D$4:$D$6003,E$14) -> 0 | F21: =SUM(B21:E21) -> 144574.61
A22: Frozen | B22: =SUMIFS(Detail!$L$4:$L$6003,Detail!$G$4:$G$6003,$A22,Detail!$D$4:$D$6003,B$14) -> 28068.45 | C22: =SUMIFS(Detail!$L$4:$L$6003,Detail!$G$4:$G$6003,$A22,Detail!$D$4:$D$6003,C$14) -> 15043.09 | D22: =SUMIFS(Detail!$L$4:$L$6003,Detail!$G$4:$G$6003,$A22,Detail!$D$4:$D$6003,D$14) -> 20210.76 | E22: =SUMIFS(Detail!$L$4:$L$6003,Detail!$G$4:$G$6003,$A22,Detail!$D$4:$D$6003,E$14) -> 0 | F22: =SUM(B22:E22) -> 63322.3
A23: Beverage | B23: =SUMIFS(Detail!$L$4:$L$6003,Detail!$G$4:$G$6003,$A23,Detail!$D$4:$D$6003,B$14) -> 28960.13 | C23: =SUMIFS(Detail!$L$4:$L$6003,Detail!$G$4:$G$6003,$A23,Detail!$D$4:$D$6003,C$14) -> 15691.64 | D23: =SUMIFS(Detail!$L$4:$L$6003,Detail!$G$4:$G$6003,$A23,Detail!$D$4:$D$6003,D$14) -> 17720.92 | E23: =SUMIFS(Detail!$L$4:$L$6003,Detail!$G$4:$G$6003,$A23,Detail!$D$4:$D$6003,E$14) -> 0 | F23: =SUM(B23:E23) -> 62372.69
A24: Disposables | B24: =SUMIFS(Detail!$L$4:$L$6003,Detail!$G$4:$G$6003,$A24,Detail!$D$4:$D$6003,B$14) -> 21451.67 | C24: =SUMIFS(Detail!$L$4:$L$6003,Detail!$G$4:$G$6003,$A24,Detail!$D$4:$D$6003,C$14) -> 18798.17 | D24: =SUMIFS(Detail!$L$4:$L$6003,Detail!$G$4:$G$6003,$A24,Detail!$D$4:$D$6003,D$14) -> 13000.44 | E24: =SUMIFS(Detail!$L$4:$L$6003,Detail!$G$4:$G$6003,$A24,Detail!$D$4:$D$6003,E$14) -> 0 | F24: =SUM(B24:E24) -> 53250.28
A25: Chemicals | B25: =SUMIFS(Detail!$L$4:$L$6003,Detail!$G$4:$G$6003,$A25,Detail!$D$4:$D$6003,B$14) -> 10568.41 | C25: =SUMIFS(Detail!$L$4:$L$6003,Detail!$G$4:$G$6003,$A25,Detail!$D$4:$D$6003,C$14) -> 8008.69 | D25: =SUMIFS(Detail!$L$4:$L$6003,Detail!$G$4:$G$6003,$A25,Detail!$D$4:$D$6003,D$14) -> 1979.43 | E25: =SUMIFS(Detail!$L$4:$L$6003,Detail!$G$4:$G$6003,$A25,Detail!$D$4:$D$6003,E$14) -> 0 | F25: =SUM(B25:E25) -> 20556.53
A26: Fees | B26: =SUMIFS(Detail!$L$4:$L$6003,Detail!$G$4:$G$6003,$A26,Detail!$D$4:$D$6003,B$14) -> 1699 | C26: =SUMIFS(Detail!$L$4:$L$6003,Detail!$G$4:$G$6003,$A26,Detail!$D$4:$D$6003,C$14) -> 1150.75 | D26: =SUMIFS(Detail!$L$4:$L$6003,Detail!$G$4:$G$6003,$A26,Detail!$D$4:$D$6003,D$14) -> 784.25 | E26: =SUMIFS(Detail!$L$4:$L$6003,Detail!$G$4:$G$6003,$A26,Detail!$D$4:$D$6003,E$14) -> 0 | F26: =SUM(B26:E26) -> 3634
A27: Total | B27: =SUM(B15:B26) -> 354685.91 | C27: =SUM(C15:C26) -> 252035.02 | D27: =SUM(D15:D26) -> 200505.57 | E27: =SUM(E15:E26) -> 25798.72 | F27: =SUM(F15:F26) -> 833025.22
